---
title: "基本异常处理"
date: 2025-02-12T14:07:59+08:00
---

在上一节关于异常需求的课中，我们讨论了使用返回代码如何导致控制流和错误流混合，从而约束两者。C++中的异常是使用三个关键字来实现的，这三个关键字相互关联：throw、try和catch。

***
## 正在引发异常

在现实生活中，我们一直使用信号来注意特定事件的发生。例如，在美式足球比赛中，如果一名球员犯规，裁判会将一面旗帜扔在地上，并用口哨吹死这场比赛。然后评估并执行处罚。一旦处罚得到处理，比赛通常会恢复正常。

在C++中，throw语句用于发出异常或错误情况发生的信号（考虑抛出惩罚标志）。发出异常发生的信号通常也被称为引发异常。

要使用throw语句，只需使用throwkeyword，后跟希望用于表示发生错误的任何数据类型的值。通常，该值将是错误代码、问题描述或自定义异常类。

下面是一些示例：

```C++
throw -1; // throw a literal integer value
throw ENUM_INVALID_INDEX; // throw an enum value
throw "Can not take square root of negative number"; // throw a literal C-style (const char*) string
throw dX; // throw a double variable that was previously defined
throw MyException("Fatal Error"); // Throw an object of class MyException
```

这些语句中的每一个都充当需要处理的某种问题发生的信号。

***
## 正在查找例外情况

引发异常只是异常处理过程的一部分。让我们回到我们的美式足球类比：一旦裁判抛出了罚球旗，接下来会发生什么？球员注意到发生了点球并停止比赛。足球比赛的正常进行被打乱了。

在C++中，我们使用try关键字来定义语句块（称为try块）。try块充当观察者，查找由try块中的任何语句引发的任何异常。

下面是try块的示例：

```C++
try
{
    // Statements that may throw exceptions you want to handle go here
    throw -1; // here's a trivial throw statement
}
```

注意，try块没有定义如何处理异常。它只是告诉程序，“嘿，如果这个try块中的任何语句抛出异常，抓住它！”。

***
## 异常处理

最后，我们的美式足球类比结束了：在点球被判罚并且比赛停止后，裁判评估点球并执行它。换句话说，在恢复正常比赛之前，必须处理好点球。

实际上，处理异常是catch块的工作。catch关键字用于定义代码块（称为catch块），该代码块处理单个数据类型的异常。

下面是将捕获整数异常的catch块的示例：

```C++
catch (int x)
{
    // Handle an exception of type int here
    std::cerr << "We caught an int exception with value" << x << '\n';
}
```

Try块和catch块一起工作——Try块检测Try块中的语句抛出的任何异常，并将它们路由到具有匹配类型的catch块进行处理。try块后面必须紧跟至少一个catch块，但可以按顺序列出多个catch模块。

一旦异常被try块捕获并路由到匹配的catch块进行处理，则认为该异常已被处理。在匹配的catch块执行后，执行然后恢复正常，从最后一个catch块之后的第一条语句开始。

Catch参数的工作方式与函数参数类似，参数在后续的Catch块中可用。基本类型的异常可以由值捕获，但非基本类型的例外应该由常量引用捕获，以避免进行不必要的复制（在某些情况下，防止切片）。

与函数一样，如果参数不打算在catch块中使用，则可以省略变量名：

```C++
catch (double) // note: no variable name since we don't use it in the catch block below
{
    // Handle exception of type double here
    std::cerr << "We caught an exception of type double\n";
}
```

这有助于防止编译器对未使用的变量发出警告。

不会对异常进行类型转换（因此不会转换int异常以匹配具有双参数的catch块）。

***
## 掷、试、接球

下面是一个使用throw、try和多个catch块的完整程序：

```C++
#include <iostream>
#include <string>

int main()
{
    try
    {
        // Statements that may throw exceptions you want to handle go here
        throw -1; // here's a trivial example
    }
    catch (double) // no variable name since we don't use the exception itself in the catch block below
    {
        // Any exceptions of type double thrown within the above try block get sent here
        std::cerr << "We caught an exception of type double\n";
    }
    catch (int x)
    {
        // Any exceptions of type int thrown within the above try block get sent here
        std::cerr << "We caught an int exception with value: " << x << '\n';
    }
    catch (const std::string&) // catch classes by const reference
    {
        // Any exceptions of type std::string thrown within the above try block get sent here
        std::cerr << "We caught an exception of type std::string\n";
    }

    // Execution continues here after the exception has been handled by any of the above catch blocks
    std::cout << "Continuing on our merry way\n";

    return 0;
}
```

在作者的计算机上，运行上述try/catch块会产生以下结果：

throw语句用于引发值为-1的异常，该异常属于int类型。然后，throw语句被封闭的try块捕获，并路由到处理int类型异常的适当catch块。该catch块打印了适当的错误消息。

一旦异常被处理，程序在捕获块后继续正常运行，并打印“继续我们的快乐之路”。

***
## 重新封装异常处理

异常处理实际上相当简单，下面两段涵盖了您需要记住的大部分内容：

当引发异常时（使用throw），运行的程序会查找最近的封闭try块（如果需要查找封闭try区块，则向上传播堆栈——我们将在下一课中更详细地讨论这一点），以查看附加到try块的任何catch处理程序是否可以处理该类型的异常。如果是这样，则执行跳到catch块的顶部，该异常被认为已处理。

如果最近的封闭try块中不存在适当的catch处理程序，则程序将继续查看后续封闭try区块中的catch处理器。如果在程序结束之前找不到适当的捕获处理程序，则程序将失败，并出现运行时异常错误。

请注意，当将异常与catch块匹配时，程序不会执行隐式转换或提升！例如，char异常将与int catch块不匹配。int异常将与浮点捕获块不匹配。然而，将执行从派生类到其父类之一的强制转换。

这就是它的全部内容。本章的其余部分将致力于展示这些原则在工作中的示例。

***
## 立即处理异常

下面是一个简短的程序，演示如何立即处理异常：

```C++
#include <iostream>

int main()
{
    try
    {
        throw 4.5; // throw exception of type double
        std::cout << "This never prints\n";
    }
    catch (double x) // handle exception of type double
    {
        std::cerr << "We caught a double of value: " << x << '\n';
    }

    return 0;
}
```

这个程序非常简单。发生的情况如下：throw语句是执行的第一个语句——这导致引发double类型的异常。执行立即移动到最近的封闭try块，这是该程序中唯一的try块。然后检查catch处理程序，以查看是否有任何处理程序匹配。我们的异常是double类型，因此我们正在寻找double型的catch处理程序。我们有一个，所以它执行。

因此，该程序的结果如下：

请注意，从不打印“This never prints”，因为异常导致执行路径立即跳转到双精度数的异常处理程序。

***
## 一个更现实的例子

让我们看一个不太学术的例子：

```C++
#include <cmath> // for sqrt() function
#include <iostream>

int main()
{
    std::cout << "Enter a number: ";
    double x {};
    std::cin >> x;

    try // Look for exceptions that occur within try block and route to attached catch block(s)
    {
        // If the user entered a negative number, this is an error condition
        if (x < 0.0)
            throw "Can not take sqrt of negative number"; // throw exception of type const char*

        // Otherwise, print the answer
        std::cout << "The sqrt of " << x << " is " << std::sqrt(x) << '\n';
    }
    catch (const char* exception) // catch exceptions of type const char*
    {
        std::cerr << "Error: " << exception << '\n';
    }
}
```

在此代码中，要求用户输入数字。如果输入正数，则不会执行If语句，不会引发异常，并打印数字的平方根。因为在这种情况下不会引发异常，所以catch块内的代码从不执行。结果如下：

如果用户输入负数，则抛出constchar类型的异常。因为我们在try块中，并且找到了匹配的异常处理程序，所以控制立即转移到constchar异常处理程序。结果是：

现在，您应该已经了解了异常背后的基本思想。在下一课中，我们将再举几个例子来展示异常的灵活性。

***
## 捕获块通常做什么

如果异常被路由到catch块，则即使catch块为空，也会将其视为“已处理”。然而，通常您希望捕获块执行一些有用的操作。当捕获块捕获异常时，它们通常做四件事：

首先，catch块可以打印错误（到控制台或日志文件），然后允许函数继续。

其次，catch块可以将值或错误代码返回给调用者。

第三，catch块可能会引发另一个异常。因为catch块在try块之外，所以在这种情况下新抛出的异常不由前一个try块处理——它由下一个封闭的try块来处理。

第四，main（）中的catch块可以用于捕获致命错误并以干净的方式终止程序。

