---
title: "重新引发异常"
date: 2025-02-12T14:07:59+08:00
---

有时，您可能会遇到这样的情况，即您希望捕获异常，但不希望（或没有能力）在捕获它的时候完全处理它。当您希望记录错误，但将问题传递给调用者以实际处理时，这是常见的。

当函数可以使用返回代码时，这很简单。考虑以下示例：

```C++
Database* createDatabase(std::string filename)
{
    Database* d {};

    try
    {
        d = new Database{};
        d->open(filename); // assume this throws an int exception on failure
        return d;
    }
    catch (int exception)
    {
        // Database creation failed
        delete d;
        // Write an error to some global logfile
        g_log.logError("Creation of Database failed");
    }

    return nullptr;
}
```

在上面的代码片段中，函数的任务是创建Database对象、打开数据库并返回Database对象。在出现错误的情况下（例如，传入了错误的文件名），异常处理程序会记录错误，然后合理地返回空指针。

现在考虑以下函数：

```C++
int getIntValueFromDatabase(Database* d, std::string table, std::string key)
{
    assert(d);

    try
    {
        return d->getIntValue(table, key); // throws int exception on failure
    }
    catch (int exception)
    {
        // Write an error to some global logfile
        g_log.logError("getIntValueFromDatabase failed");

        // However, we haven't actually handled this error
        // So what do we do here?
    }
}
```

在该函数成功的情况下，它返回一个整数值——任何整数值都可以是有效值。

但getIntValue（）出现问题的情况如何？在这种情况下，getIntValue（）将引发整数异常，该异常将被getIntValueFromDatabase（）中的catch块捕获，该块将记录错误。但是，我们如何告诉getIntValueFromDatabase（）的调用方出现了问题？与上面的示例不同，这里没有一个好的返回代码可以使用（因为任何整数返回值都可以是有效的）。

引发新的异常

一个明显的解决方案是抛出新的异常。

```C++
int getIntValueFromDatabase(Database* d, std::string table, std::string key)
{
    assert(d);

    try
    {
        return d->getIntValue(table, key); // throws int exception on failure
    }
    catch (int exception)
    {
        // Write an error to some global logfile
        g_log.logError("getIntValueFromDatabase failed");

        // Throw char exception 'q' up the stack to be handled by caller
        throw 'q'; 
    }
}
```

在上面的示例中，程序从getIntValue（）捕获int异常，记录错误，然后抛出一个字符值为“q”的新异常。尽管从catch块抛出异常似乎很奇怪，但这是允许的。请记住，只有在try块中引发的异常才有资格被捕获。这意味着在catch块中引发的异常将不会被它所在的catch块捕获。相反，它将向上传播到堆栈中的调用方。

从catch块引发的异常可以是任何类型的异常——它不需要与刚刚捕获的异常的类型相同。

重新引发异常（错误的方式）

另一个选项是重新引发相同的异常。这样做的一种方法如下：

```C++
int getIntValueFromDatabase(Database* d, std::string table, std::string key)
{
    assert(d);

    try
    {
        return d->getIntValue(table, key); // throws int exception on failure
    }
    catch (int exception)
    {
        // Write an error to some global logfile
        g_log.logError("getIntValueFromDatabase failed");

        throw exception;
    }
}
```

尽管这种方法有效，但它有几个缺点。首先，这不会抛出与捕获的异常完全相同的异常——相反，它抛出变量异常的副本初始化副本。尽管编译器可以自由删除副本，但它可能不能，因此这可能会降低性能。

但值得注意的是，考虑在以下情况下会发生什么：

```C++
int getIntValueFromDatabase(Database* d, std::string table, std::string key)
{
    assert(d);

    try
    {
        return d->getIntValue(table, key); // throws Derived exception on failure
    }
    catch (Base& exception)
    {
        // Write an error to some global logfile
        g_log.logError("getIntValueFromDatabase failed");

        throw exception; // Danger: this throws a Base object, not a Derived object
    }
}
```

在这种情况下，getIntValue（）抛出Derived对象，但catch块捕获的是Base引用。这很好，因为我们知道可以对衍生对象具有Base引用。然而，当我们抛出异常时，抛出的异常是从变量异常中复制初始化的。变量异常的类型为Base，因此复制初始化异常的类型也为Base（而不是Derived！）。换句话说，我们的派生对象已经被切片！

您可以在以下程序中看到这一点：

```C++
#include <iostream>
class Base
{
public:
    Base() {}
    virtual void print() { std::cout << "Base"; }
};

class Derived: public Base
{
public:
    Derived() {}
    void print() override { std::cout << "Derived"; }
};

int main()
{
    try
    {
        try
        {
            throw Derived{};
        }
        catch (Base& b)
        {
            std::cout << "Caught Base b, which is actually a ";
            b.print();
            std::cout << '\n';
            throw b; // the Derived object gets sliced here
        }
    }
    catch (Base& b)
    {
        std::cout << "Caught Base b, which is actually a ";
        b.print();
        std::cout << '\n';
    }

    return 0;
}
```

这将打印：

第二行指示Base实际上是Base而不是Derived的事实证明Deriveed对象已被切片。

重新引发异常（正确的方式）

幸运的是，C++提供了一种重新抛出与刚刚捕获的异常完全相同的异常的方法。为此，只需在catch块中使用throw关键字（没有关联的变量），如下所示：

```C++
#include <iostream>
class Base
{
public:
    Base() {}
    virtual void print() { std::cout << "Base"; }
};

class Derived: public Base
{
public:
    Derived() {}
    void print() override { std::cout << "Derived"; }
};

int main()
{
    try
    {
        try
        {
            throw Derived{};
        }
        catch (Base& b)
        {
            std::cout << "Caught Base b, which is actually a ";
            b.print();
            std::cout << '\n';
            throw; // note: We're now rethrowing the object here
        }
    }
    catch (Base& b)
    {
        std::cout << "Caught Base b, which is actually a ";
        b.print();
        std::cout << '\n';
    }

    return 0;
}
```

这将打印：

这个似乎没有抛出任何特定内容的throw关键字实际上重新抛出了刚刚捕获的完全相同的异常。没有制作拷贝，这意味着我们不必担心性能降低拷贝或切片。

如果需要重新抛出异常，则应首选此方法而不是其他方法。

{{< alert success >}}
**规则**

重新引发相同的异常时，请单独使用throw关键字

{{< /alert >}}

