---
title: "例外规范和noexcept"
date: 2025-02-12T14:07:59+08:00
---

（请与读者Koe联系，以提供本课的初稿！）

查看典型的函数声明，无法确定函数是否可能引发异常：

```C++
int doSomething(); // can this function throw an exception or not?
```

在上面的示例中，doSomething（）是否可以引发异常？现在还不清楚。但在某些情况下，答案是重要的。在第27.8课——异常的危险和缺点中，我们描述了在堆栈展开期间从析构函数中抛出的异常如何导致程序停止。如果doSomething（）可以引发异常，那么从析构函数（或不希望引发异常的任何其他位置）调用它是有风险的。尽管我们可以让析构函数处理doSomething（）引发的异常（因此这些异常不会传播到析构函数之外），但我们必须记住这样做，并且我们必须确保覆盖可能引发的所有不同类型的异常。

虽然注释可能有助于枚举函数是否引发异常（如果是，则是什么类型的异常），但文档可能会变得过时，并且编译器不会强制注释。

异常规范是一种语言机制，最初设计用于记录函数可能作为函数规范的一部分抛出的异常类型。虽然大多数异常规范现在都已弃用或删除，但添加了一个有用的异常规范作为替代，我们将在本课中介绍。

***
## noexcept说明符

在C++中，所有函数都被分类为非抛出或潜在抛出。非抛出函数是承诺不抛出调用方可见的异常的函数。可能引发的函数可能会引发调用方可见的异常。

要将函数定义为非抛出，可以使用noexcept说明符。为此，我们在函数声明中使用noexcept关键字，放在函数参数列表的右侧：

```C++
void doSomething() noexcept; // this function is specified as non-throwing
```

注意，noexcept实际上并不阻止函数抛出异常或调用其他可能抛出的函数。只要noexcept函数在内部捕获和处理这些异常，并且这些异常不退出noexception函数，就允许这样做。

如果未处理的异常将退出noexcept函数，则将调用std:：terminate（即使存在异常处理程序，该异常处理程序将在堆栈的某个位置处理此类异常）。并且，如果从noexcept函数内部调用std:：terminate，堆栈展开可能会发生，也可能不会发生（取决于实现和优化），这意味着在终止之前，对象可能会被正确销毁，也可能没有被正确销毁。

与仅在返回值上不同的函数很相似，不能重载仅在异常规范上不同的功能。

{{< alert success >}}
**关键洞察力**

noexcept函数做出的不抛出调用方可见的异常的承诺是契约承诺，而不是编译器强制执行的承诺。因此，虽然调用noexcept函数应该是安全的，但noexception函数中导致契约被破坏的任何异常处理错误都将导致程序终止！这不应该发生，但错误也不应该发生。

由于这个原因，最好不要让noexcept函数与异常混淆，或者调用可能引发异常的抛出函数。如果一开始不可能引发异常，则noexcept函数不能有异常处理错误！

{{< /alert >}}

***
## 说明noexcept函数和异常的行为

以下程序说明了各种情况下noexcept函数和异常的行为：

```C++
// h/t to reader yellowEmu for the first draft of this program
#include <iostream>

class Doomed
{
public:
    ~Doomed()
    {
        std::cout << "Doomed destructed\n";
    }
};

void thrower()
{
    std::cout << "Throwing exception\n";
    throw 1;
}

void pt()
{
    std::cout << "pt (potentally throwing) called\n";
    //This object will be destroyed during stack unwinding (if it occurs)
    Doomed doomed{};
    thrower();
    std::cout << "This never prints\n";
}

void nt() noexcept
{
    std::cout << "nt (noexcept) called\n";
    //This object will be destroyed during stack unwinding (if it occurs)
    Doomed doomed{};
    thrower();
    std::cout << "this never prints\n";
}

void tester(int c) noexcept
{
    std::cout << "tester (noexcept) case " << c << " called\n";
    try
    {
        (c == 1) ? pt() : nt();
    }
    catch (...)
    {
        std::cout << "tester caught exception\n";
    }
}

int main()
{
    std::cout << std::unitbuf; // flush buffer after each insertion
    std::cout << std::boolalpha; // print boolean as true/false
    tester(1);
    std::cout << "Test successful\n\n";
    tester(2);
    std::cout << "Test successful\n";

    return 0;
}
```

在作者的机器上，该程序打印：

然后程序中止。

让我们更详细地了解一下这里发生了什么。注意，tester是一个noexcept函数，因此承诺不会向调用方（main）公开任何异常。

第一种情况说明，noexcept函数可以调用潜在的抛出函数，甚至可以处理这些函数抛出的任何异常。首先，调用tester（1），它调用潜在的抛出函数pt，该函数调用抛出器，抛出异常。该异常的第一个处理程序在tester中，因此该异常展开堆栈（销毁在该过程中注定要失败的局部变量），并在tester内捕获和处理该异常。由于测试程序不向调用者（main）公开此异常，因此这里没有违反noexcept，并且控件返回到main。

第二种情况说明了当noexcept函数试图将异常传递回其调用方时发生的情况。首先，调用tester（2），它调用非抛出函数nt，该函数调用抛出器，抛出异常。此异常的第一个处理程序在测试仪中。然而，nt是noexcept，为了到达tester中的处理程序，异常必须传播到nt的调用方。这违反了nt的noexception，因此调用了std:：terminate，我们的程序立即中止。在作者的机器上，堆栈没有被解开（如注定不会被销毁所示）。

***
## 具有布尔参数的noexcept说明符

noexcept说明符具有可选的布尔参数。noexcept（true）相当于noexception，这意味着函数是非抛出的。noexcept（false）表示函数可能正在抛出。这些参数通常仅用于模板函数，因此可以基于某些参数化值动态创建模板函数作为非抛出或潜在抛出。

***
## 哪些功能是非抛出和潜在抛出

隐式不抛出的函数：

1. 析构函数


对于隐式声明或默认函数，默认情况下不会引发的函数：

1. 构造函数：默认、复制、移动
2. 分配：复制、移动
3. 比较运算符（从C++20开始）


然而，如果这些函数中的任何一个调用（显式或隐式）另一个可能引发的函数，则所列出的函数也将被视为可能引发。例如，如果类具有具有潜在抛出构造函数的数据成员，则该类的构造函数也将被视为潜在抛出。作为另一个示例，如果复制分配操作符调用可能引发的分配操作符，则复制分配也可能引发。

可能引发的函数（如果未隐式声明或默认）：

1. 正常功能
2. 用户定义的构造函数
3. 用户定义的运算符


***
## noexcept运算符

noexcept运算符也可以在表达式内部使用。它接受表达式作为参数，如果编译器认为它将抛出异常或不抛出异常，则返回true或false。noexcept操作符在编译时静态检查，并且不会实际计算输入表达式。

```C++
void foo() {throw -1;}
void boo() {};
void goo() noexcept {};
struct S{};

constexpr bool b1{ noexcept(5 + 3) }; // true; ints are non-throwing
constexpr bool b2{ noexcept(foo()) }; // false; foo() throws an exception
constexpr bool b3{ noexcept(boo()) }; // false; boo() is implicitly noexcept(false)
constexpr bool b4{ noexcept(goo()) }; // true; goo() is explicitly noexcept(true)
constexpr bool b5{ noexcept(S{}) };   // true; a struct's default constructor is noexcept by default
```

noexcept运算符可以用于根据代码是否可能引发来有条件地执行代码。这是实现某些异常安全保证所必需的，我们将在下一节中讨论。

***
## 例外安全保证

异常安全保证是关于发生异常时函数或类的行为的合同指南。异常安全保障有四个级别：

1. 无保证——不能保证如果抛出异常会发生什么（例如，类可能处于不可用状态）
2. 基本保证——如果抛出异常，则不会泄漏内存，并且对象仍然可用，但程序可能处于修改状态。
3. 强保证——如果抛出异常，则不会泄漏内存，并且不会更改程序状态。这意味着函数必须完全成功，或者在失败时没有副作用。如果故障发生在最初修改任何内容之前，这很容易，但也可以通过回滚任何更改来实现，以便程序返回到故障前状态。
4. 无抛出/无失败保证——函数将始终成功（无失败）或失败，而不会引发向调用方公开的异常（无抛出）。如果未公开，则可能在内部引发异常。noexcept说明符映射到此级别的异常安全保证。


让我们更详细地看一下无抛出/无失败保证：

无抛出保证：如果函数失败，则不会抛出异常。相反，它将返回错误代码或忽略问题。当异常已经被处理时，在堆栈展开期间不需要抛出保证；例如，所有析构函数都应该有无抛出保证（就像那些析构函数调用的任何函数一样）。不应抛出的代码示例：

1. 析构函数和内存释放/清理函数
2. 高级无抛出函数需要调用的函数


无失败保证：函数将总是成功地完成它试图执行的操作（因此从不需要抛出异常，因此，无失败是一种略强的无抛出形式）。不应失败的代码示例：

1. 移动构造函数和移动赋值（移动语义，在第22章中介绍）
2. 交换函数
3. 容器上的清除/擦除/重置功能
4. 对std:：unique_ptr的操作（也在第22章中介绍）
5. 高级无故障函数需要调用的函数


***
## 何时使用noexcept

仅仅因为代码没有显式抛出任何异常，并不意味着您应该在代码周围撒上noexcept。默认情况下，大多数函数都可能引发，因此如果您的函数调用其他函数，则很可能它调用了可能引发的函数，因此也可能引发。

有几个很好的理由将函数标记为非抛出：

1. 可以从非异常安全的函数（如析构函数）中安全地调用非抛出函数
2. noexcept函数可以使编译器执行一些在其他情况下不可用的优化。由于noexcept函数不能在函数外部引发异常，编译器不必担心将运行时堆栈保持在可展开状态，这可以使它生成更快的代码。
3. 在一些重要的情况下，知道函数是noexcept允许我们在自己的代码中产生更有效的实现：标准库容器（如std:：vector）是noexce感知的，并将使用noexception操作符来确定在某些地方是使用移动语义（更快）还是复制语义（较慢）。我们在第22章中介绍了移动语义，在第27.10课中介绍了这种优化——std:：move_if_noexcept。


标准库的策略是仅在不能引发或失败的函数上使用noexcept。可能引发但实际上不引发异常（由于实现）的函数通常不会标记为noexcept。

对于您自己的代码，始终将以下标记为noexcept：

1. 移动构造函数
2. 移动分配运算符
3. Swap函数


对于您的代码，请考虑将以下标记为noexcept：

1. 要表示无抛出或无失败保证的函数（例如，记录可以从析构函数或其他noexcept函数安全调用它们）
2. 复制没有抛出的构造函数和复制赋值运算符（以利用优化）。
3. 析构函数。析构函数隐式为noexcept，除非所有成员都具有noexceptive析构函数


{{< alert success >}}
**最佳做法**

始终生成移动构造函数、移动赋值和交换函数noexcept。

除非可以，否则不要复制构造函数和赋值运算符。

在其他函数上使用noexcept来表示无故障或无抛出保证。

{{< /alert >}}

{{< alert success >}}
**最佳做法**

如果您不确定函数是否应该具有无故障/无抛出保证，那么出于谨慎的考虑，请不要用noexcept标记它。撤消使用noexcept的决定违反了对用户关于函数行为的接口承诺，并且可能会破坏现有代码。通过在最初不是noexcept的函数中添加noexception来增强保证被认为是安全的。

{{< /alert >}}

***
## 动态异常规范

{{< alert success >}}
**可选读数**

在C++11之前和C++17之前，使用动态异常规范来代替noexcept。动态异常规范语法使用throw关键字列出函数可以直接或间接引发的异常类型：

```C++
int doSomething() throw(); // does not throw exceptions
int doSomething() throw(std::out_of_range, int*); // may throw either std::out_of_range or a pointer to an integer
int doSomething() throw(...); // may throw anything
```

由于不完整的编译器实现、与模板函数的一些不兼容、对它们如何工作的常见误解以及标准库大多不使用它们的事实，动态异常规范在C++11中被弃用，并从C++17和C++20的语言中删除。有关更多上下文，请参阅本文。

{{< /alert >}}

